Workbook

Sheet parameter_metadata
A1: =parameter_metadata_original!A1 -> category | B1: =parameter_metadata_original!B1 -> Relevant for use case | C1: =parameter_metadata_original!C1 -> sub_category | D1: =parameter_metadata_original!D1 -> parameter | E1: =parameter_metadata_original!E1 -> order_parameter | F1: =parameter_metadata_original!F1 -> subparameter | G1: =parameter_metadata_original!G1 -> access | H1: =parameter_metadata_original!H1 -> type | ... K1: =parameter_metadata_original!K1 -> data model definition string
A2: =parameter_metadata_original!A3 -> 1. General product and manufacturer information | B2: =parameter_metadata_original!B3 -> x | C2: =parameter_metadata_original!C3 -> General product and manufacturer information | D2: =parameter_metadata_original!D3 -> Product ID | E2: 1 | G2: =parameter_metadata_original!G3 -> Public | H2: =parameter_metadata_original!H3 -> Static | I2: =parameter_metadata_original!I3 -> 0 | J2: 1 | K2: =parameter_metadata_original!K3 -> {"Product ID": {"@type":"gs1:gtin","value": {"@value":"", "@type":"xsd:string"}}}
A3: =parameter_metadata_original!A5 -> 1. General product and manufacturer information | B3: =parameter_metadata_original!B5 -> x | C3: =parameter_metadata_original!C5 -> General product and manufacturer information | D3: =parameter_metadata_original!D5 -> Manufacturing date | E3: 3 | G3: =parameter_metadata_original!G5 -> Public | H3: =parameter_metadata_original!H5 -> Static | I3: =parameter_metadata_original!I5 -> 0 | K3: =parameter_metadata_original!K5 -> {"Manufacturing date": {"@type":"gs1:productionDateTime", "value": {"@value":"", "@type":"xsd:dateTime"}}}
A4: =parameter_metadata_original!A6 -> 1. General product and manufacturer information | B4: =parameter_metadata_original!B6 -> x | C4: =parameter_metadata_original!C6 -> General product and manufacturer information | D4: =parameter_metadata_original!D6 -> Manufactured by | E4: 4 | G4: =parameter_metadata_original!G6 -> Public | H4: =parameter_metadata_original!H6 -> Static | I4: =parameter_metadata_original!I6 -> ONEPan AB, Bögatan 1, SE-412 72 Göteborg, Sweden | J4: =parameter_metadata_original!J6 -> ONEPan AB, Bögatan 1, SE-412 72 Göteborg, Sweden | K4: =parameter_metadata_original!K6 -> {"Manufactured by": {"@type":"gs1:organizationName", "value": {"@value": "", "@type":"xsd:string"}}}
A5: =parameter_metadata_original!A7 -> 1. General product and manufacturer information | B5: =parameter_metadata_original!B7 -> x | C5: =parameter_metadata_original!C7 -> General product and manufacturer information | D5: =parameter_metadata_original!D7 -> Manufacturing place | E5: 5 | F5: =parameter_metadata_original!F7 -> [City, Address] | G5: =parameter_metadata_original!G7 -> Public | H5: =parameter_metadata_original!H7 -> Static | I5: =parameter_metadata_original!I7 -> [Poland, Main Street 34] | J5: =parameter_metadata_original!J7 -> [Poland, Main Street 34] | K5: =parameter_metadata_original!K7 -> {"Manufacturing place" : {"@type":"gs1:address", "City": {"@type":"gs1:addressLocality", "value":{"@value": "", "@type":"xsd:string"}} , "Address":{"@type":"gs1:streetAddress", "value":{"@value": "", "@type":"xsd:string"}}}}
A6: =parameter_metadata_original!A8 -> 1. General product and manufacturer information | B6: =parameter_metadata_original!B8 -> x | C6: =parameter_metadata_original!C8 -> General product and manufacturer information | D6: =parameter_metadata_original!D8 -> Product category | E6: 6 | G6: =parameter_metadata_original!G8 -> Public | H6: =parameter_metadata_original!H8 -> Static | I6: =parameter_metadata_original!I8 -> Cookware | J6: =parameter_metadata_original!J8 -> Cookware | K6: =parameter_metadata_original!K8 -> {"Product category" : {"@type":"gs1:brandName", "value":{"@value":"", "@type":"rdf:langString"}}}
A7: =parameter_metadata_original!A9 -> 1. General product and manufacturer information | B7: =parameter_metadata_original!B9 -> x | C7: =parameter_metadata_original!C9 -> General product and manufacturer information | D7: =parameter_metadata_original!D9 -> Economic operator | E7: 7 | G7: =parameter_metadata_original!G9 -> Public | H7: =parameter_metadata_original!H9 -> Static | I7: =parameter_metadata_original!I9 -> ONEPan AB | J7: =parameter_metadata_original!J9 -> ONEPan AB | K7: =parameter_metadata_original!K9 -> {"Economic operator" : {"@type":"schema:legalName", "value": {"@value":"", "@type":"xsd:string"}}}
A8: =parameter_metadata_original!A14 -> 1. General product and manufacturer information | B8: =parameter_metadata_original!B14 -> x | C8: =parameter_metadata_original!C14 -> Product specification | D8: =parameter_metadata_original!D14 -> Original weight | E8: 8 | G8: =parameter_metadata_original!G14 -> Public | H8: =parameter_metadata_original!H14 -> Static | I8: =parameter_metadata_original!I14 -> 1.7 | J8: =parameter_metadata_original!J14 -> 2.7 | K8: =parameter_metadata_original!K14 -> {"Original weight" : {"value":{"@value":"", "@type":"xsd:float", "unitCode":"KGM"}}}
A9: =parameter_metadata_original!A15 -> 1. General product and manufacturer information | B9: =parameter_metadata_original!B15 -> x | C9: =parameter_metadata_original!C15 -> Product specification | D9: =parameter_metadata_original!D15 -> Dimensions | E9: 9 | G9: =parameter_metadata_original!G15 -> Public | H9: =parameter_metadata_original!H15 -> Static | I9: =parameter_metadata_original!I15 -> Diameter 28 cm; Height 5 cm; Thickness bottom plate 0.55 cm; Handle length 21 cm | J9: =parameter_metadata_original!J15 -> Diameter 28 cm; Height 5 cm; Thickness bottom plate 0.55 cm; Handle length 21 cm | K9: =parameter_metadata_original!K15 -> {"Dimensions":{ "value": {"@value":"", "@type":"xsd:string"}}}
A10: =parameter_metadata_original!A22 -> 1. General product and manufacturer information | B10: =parameter_metadata_original!B22 -> x | C10: =parameter_metadata_original!C22 -> General product and manufacturer information | D10: =parameter_metadata_original!D22 -> Date of purchase | E10: 10 | G10: =parameter_metadata_original!G22 -> Public | H10: =parameter_metadata_original!H22 -> Static | I10: =parameter_metadata_original!I22 -> 0 | K10: =parameter_metadata_original!K22 -> {"Date of purchase" : {"value":{"@value":"", "@type":"xsd:dateTime"}}}
A11: =parameter_metadata_original!A23 -> 1. General product and manufacturer information | B11: =parameter_metadata_original!B23 -> x | C11: =parameter_metadata_original!C23 -> General product and manufacturer information | D11: =parameter_metadata_original!D23 -> Date of product registration on website | E11: 11 | G11: =parameter_metadata_original!G23 -> Public | H11: =parameter_metadata_original!H23 -> Static | I11: =parameter_metadata_original!I23 -> 45541 | J11: =parameter_metadata_original!J23 -> 45541 | K11: =parameter_metadata_original!K23 -> {"Date of product registration on website" : {"value":{"@value":"", "@type":"xsd:dateTime"}}}
A12: =parameter_metadata_original!A26 -> 1. General product and manufacturer information | B12: =parameter_metadata_original!B26 -> x | C12: =parameter_metadata_original!C26 -> Product specification | D12: =parameter_metadata_original!D26 -> Ovenproof | E12: 12 | G12: =parameter_metadata_original!G26 -> Public | H12: =parameter_metadata_original!H26 -> Static | I12: =parameter_metadata_original!I26 -> Withstands temperatures up to 280 ºC | J12: =parameter_metadata_original!J26 -> Withstands temperatures up to 280 ºC | K12: =parameter_metadata_original!K26 -> {"Ovenproof" : {"value":{"@value":"", "@type":"xsd:string"}}}
A13: =parameter_metadata_original!A27 -> 1. General product and manufacturer information | B13: =parameter_metadata_original!B27 -> x | C13: =parameter_metadata_original!C27 -> Product specification | D13: =parameter_metadata_original!D27 -> Heat sources | E13: 13 | G13: =parameter_metadata_original!G27 -> Public | H13: =parameter_metadata_original!H27 -> Static | I13: =parameter_metadata_original!I27 -> Suitable for all heat soruces: induction, gas, open fire | J13: =parameter_metadata_original!J27 -> Suitable for all heat soruces: induction, gas, open fire | K13: =parameter_metadata_original!K27 -> {"Heat sources" : {"value":{"@value":"", "@type":"xsd:string"}}}
A14: =parameter_metadata_original!A45 -> 3. Carbon footprint | B14: =parameter_metadata_original!B45 -> x | C14: =parameter_metadata_original!C45 -> Carbon footprint | D14: =parameter_metadata_original!D45 -> CO2 footprint manufacturing (cradle to gate) (to warehouse) | E14: 14 | G14: =parameter_metadata_original!G45 -> Public | H14: =parameter_metadata_original!H45 -> Static | I14: =parameter_metadata_original!I45 -> 27 | J14: =parameter_metadata_original!J45 -> 27 | K14: =parameter_metadata_original!K45 -> {"CO2 footprint manufacturing (cradle to gate) (to warehouse)" : {"value":{"@value":"", "@type":"xsd:float", "unitCode":"CO2"}}}
A15: =parameter_metadata_original!A46 -> 3. Carbon footprint | B15: =parameter_metadata_original!B46 -> x | C15: =parameter_metadata_original!C46 -> Carbon footprint | D15: =parameter_metadata_original!D46 -> CO2 footprint refurbishment (recoating process) | E15: 15 | G15: =parameter_metadata_original!G46 -> Public | H15: =parameter_metadata_original!H46 -> Static | I15: =parameter_metadata_original!I46 -> 1.344 | J15: =parameter_metadata_original!J46 -> 1.344 | K15: =parameter_metadata_original!K46 -> {"CO2 footprint refurbishment (recoating process)" : {"value":{"@value":"", "@type":"xsd:float", "unitCode":"CO2"}}}
A16: =parameter_metadata_original!A51 -> 3. Carbon footprint | B16: =parameter_metadata_original!B51 -> x | C16: =parameter_metadata_original!C51 -> Carbon footprint | D16: =parameter_metadata_original!D51 -> CO2 footprint EOL (recycling) | E16: 16 | G16: =parameter_metadata_original!G51 -> Public | H16: =parameter_metadata_original!H51 -> Static | I16: =parameter_metadata_original!I51 -> 0 | K16: =parameter_metadata_original!K51 -> {"CO2 footprint EOL (recycling)" : {"value":{"@value":"", "@type":"xsd:float", "unitCode":"CO2"}}}
A17: =parameter_metadata_original!A52 -> 3. Carbon footprint | B17: =parameter_metadata_original!B52 -> x | C17: =parameter_metadata_original!C52 -> Carbon footprint | D17: =parameter_metadata_original!D52 -> Min allowed weight | E17: 17 | G17: =parameter_metadata_original!G52 -> Private | H17: =parameter_metadata_original!H52 -> Static | I17: =parameter_metadata_original!I52 -> 0 | K17: =parameter_metadata_original!K52 -> {"Min allowed weight" : {"value":{"@value":"", "@type":"xsd:string", "unitCode":"KGM"}}}
A18: =parameter_metadata_original!A54 -> 3. Carbon footprint | B18: =parameter_metadata_original!B54 -> x | C18: =parameter_metadata_original!C54 -> Carbon footprint | D18: =parameter_metadata_original!D54 -> Refurbished in | E18: 18 | G18: =parameter_metadata_original!G54 -> Private | H18: =parameter_metadata_original!H54 -> Static | I18: =parameter_metadata_original!I54 -> Sweden | J18: =parameter_metadata_original!J54 -> Sweden | K18: =parameter_metadata_original!K54 -> {"Refurbished in" : {"value":{"@value":"", "@type":"xsd:string"}}}
A19: =parameter_metadata_original!A19 -> 5. Material and composition | B19: =parameter_metadata_original!B19 -> x | C19: =parameter_metadata_original!C19 -> Material and composition | D19: =parameter_metadata_original!D19 -> Hazardous substances, other than Hg, Cd, Pb | E19: 19 | G19: =parameter_metadata_original!G19 -> Public | H19: =parameter_metadata_original!H19 -> Static | I19: =parameter_metadata_original!I19 -> No | J19: =parameter_metadata_original!J19 -> No | K19: =parameter_metadata_original!K19 -> {"Hazardous substances, other than Hg, Cd, Pb" : {"value":{"@value":"", "@type":"xsd:string"}}}
A20: =parameter_metadata_original!A28 -> 5. Material and composition | B20: =parameter_metadata_original!B28 -> x | C20: =parameter_metadata_original!C28 -> Components | D20: =parameter_metadata_original!D28 -> Number of components | E20: 20 | G20: =parameter_metadata_original!G28 -> Public | H20: =parameter_metadata_original!H28 -> Static | I20: =parameter_metadata_original!I28 -> 3 | J20: =parameter_metadata_original!J28 -> 4 | K20: =parameter_metadata_original!K28 -> {"Number of components" : {"value":{"@value":"", "@type":"xsd:int"}}}
A21: =parameter_metadata_original!A29 -> 5. Material and composition | B21: =parameter_metadata_original!B29 -> x | C21: =parameter_metadata_original!C29 -> Components | D21: =parameter_metadata_original!D29 -> Components | E21: 21 | G21: =parameter_metadata_original!G29 -> Public | H21: =parameter_metadata_original!H29 -> Static | I21: =parameter_metadata_original!I29 -> Bottom plate, pan body, handle, coating | J21: =parameter_metadata_original!J29 -> Bottom plate, pan body, handle, coating | K21: =parameter_metadata_original!K29 -> {"Components" : {"value":{"@value":"", "@type":"xsd:string"}}}
A22: =parameter_metadata_original!A30 -> 5. Material and composition | B22: =parameter_metadata_original!B30 -> x | C22: =parameter_metadata_original!C30 -> Components | D22: =parameter_metadata_original!D30 -> Bottom plate content | E22: 22 | G22: =parameter_metadata_original!G30 -> Public | H22: =parameter_metadata_original!H30 -> Static | I22: =parameter_metadata_original!I30 -> Stainless steel (magnetic) | J22: =parameter_metadata_original!J30 -> Stainless steel (magnetic) | K22: =parameter_metadata_original!K30 -> {"Bottom plate content" : {"value":{"@value":"", "@type":"xsd:string"}}}
A23: =parameter_metadata_original!A31 -> 5. Material and composition | B23: =parameter_metadata_original!B31 -> x | C23: =parameter_metadata_original!C31 -> Components | D23: =parameter_metadata_original!D31 -> Pan body content | E23: 23 | G23: =parameter_metadata_original!G31 -> Public | H23: =parameter_metadata_original!H31 -> Static | I23: =parameter_metadata_original!I31 -> Aluminium, 100% recycled | J23: =parameter_metadata_original!J31 -> Aluminium, 100% recycled | K23: =parameter_metadata_original!K31 -> {"Pan body content" : {"value":{"@value":"", "@type":"xsd:string"}}}
A24: =parameter_metadata_original!A32 -> 5. Material and composition | B24: =parameter_metadata_original!B32 -> x | C24: =parameter_metadata_original!C32 -> Components | D24: =parameter_metadata_original!D32 -> Handle content | E24: 24 | G24: =parameter_metadata_original!G32 -> Public | H24: =parameter_metadata_original!H32 -> Static | I24: =parameter_metadata_original!I32 -> Stainless steel | J24: =parameter_metadata_original!J32 -> Stainless steel | K24: =parameter_metadata_original!K32 -> {"Handle content" : {"value":{"@value":"", "@type":"xsd:string"}}}
A25: =parameter_metadata_original!A33 -> 5. Material and composition | B25: =parameter_metadata_original!B33 -> x | C25: =parameter_metadata_original!C33 -> Components | D25: =parameter_metadata_original!D33 -> Coating content | E25: 25 | G25: =parameter_metadata_original!G33 -> Public | H25: =parameter_metadata_original!H33 -> Static | I25: =parameter_metadata_original!I33 -> Ceramic non-stick, PFAS-free | J25: =parameter_metadata_original!J33 -> Ceramic non-stick, PFAS-free | K25: =parameter_metadata_original!K33 -> {"Coating content" : {"value":{"@value":"", "@type":"xsd:string"}}}
A26: =parameter_metadata_original!A34 -> 5. Material and composition | B26: =parameter_metadata_original!B34 -> x | C26: =parameter_metadata_original!C34 -> Components | D26: =parameter_metadata_original!D34 -> Bottom plate weight | E26: 26 | G26: =parameter_metadata_original!G34 -> Public | H26: =parameter_metadata_original!H34 -> Static | I26: =parameter_metadata_original!I34 -> 0.28 | J26: =parameter_metadata_original!J34 -> 0.28 | K26: =parameter_metadata_original!K34 -> {"Bottom plate weight" : {"value":{"@value":"", "@type":"xsd:float", "unitCode":"KGM"}}}
A27: =parameter_metadata_original!A35 -> 5. Material and composition | B27: =parameter_metadata_original!B35 -> x | C27: =parameter_metadata_original!C35 -> Components | D27: =parameter_metadata_original!D35 -> Pan body weight | E27: 27 | G27: =parameter_metadata_original!G35 -> Public | H27: =parameter_metadata_original!H35 -> Static | I27: =parameter_metadata_original!I35 -> 1.2 | J27: =parameter_metadata_original!J35 -> 1.2 | K27: =parameter_metadata_original!K35 -> {"Pan body weight" : {"value":{"@value":"", "@type":"xsd:float", "unitCode":"KGM"}}}
A28: =parameter_metadata_original!A36 -> 5. Material and composition | B28: =parameter_metadata_original!B36 -> x | C28: =parameter_metadata_original!C36 -> Components | D28: =parameter_metadata_original!D36 -> Handle weight | E28: 28 | G28: =parameter_metadata_original!G36 -> Public | H28: =parameter_metadata_original!H36 -> Static | I28: =parameter_metadata_original!I36 -> 0.22 | J28: =parameter_metadata_original!J36 -> 0.22 | K28: =parameter_metadata_original!K36 -> {"Handle weight" : {"value":{"@value":"", "@type":"xsd:float", "unitCode":"KGM"}}}
A29: =parameter_metadata_original!A37 -> 5. Material and composition | B29: =parameter_metadata_original!B37 -> x | C29: =parameter_metadata_original!C37 -> Components | D29: =parameter_metadata_original!D37 -> Coating weight | E29: 29 | G29: =parameter_metadata_original!G37 -> Public | H29: =parameter_metadata_original!H37 -> Static | I29: =parameter_metadata_original!I37 -> < 0.010 | J29: =parameter_metadata_original!J37 -> < 0.011 | K29: =parameter_metadata_original!K37 -> {"Coating weight" : {"value":{"@value":"", "@type":"xsd:string", "unitCode":"KGM"}}}
A30: =parameter_metadata_original!A16 -> 6. Circularity and resource efficiency | B30: =parameter_metadata_original!B16 -> x | C30: =parameter_metadata_original!C16 -> Recycled content | D30: =parameter_metadata_original!D16 -> Recycled content | E30: 30 | G30: =parameter_metadata_original!G16 -> Public | H30: =parameter_metadata_original!H16 -> Static | I30: =parameter_metadata_original!I16 -> Aluminium | J30: =parameter_metadata_original!J16 -> Aluminium | K30: =parameter_metadata_original!K16 -> {"Recycled content" : { "value": {"@value":"", "@type":"xsd:string"}}}
A31: =parameter_metadata_original!A17 -> 6. Circularity and resource efficiency | B31: =parameter_metadata_original!B17 -> x | C31: =parameter_metadata_original!C17 -> Recycled content | D31: =parameter_metadata_original!D17 -> Recycled content weight | E31: 31 | G31: =parameter_metadata_original!G17 -> Public | H31: =parameter_metadata_original!H17 -> Static | I31: =parameter_metadata_original!I17 -> 1.2 | J31: =parameter_metadata_original!J17 -> 1.2 | K31: =parameter_metadata_original!K17 -> {"Recycled content weight" : {"value":{"@value":"", "@type":"xsd:float", "unitCode":"KGM"}}}
A32: =parameter_metadata_original!A18 -> 6. Circularity and resource efficiency | B32: =parameter_metadata_original!B18 -> x | C32: =parameter_metadata_original!C18 -> Recycled content | D32: =parameter_metadata_original!D18 -> Recycled content [share - wt%] | E32: 32 | G32: =parameter_metadata_original!G18 -> Public | H32: =parameter_metadata_original!H18 -> Static | I32: =parameter_metadata_original!I18 -> 70.2 | J32: =parameter_metadata_original!J18 -> 70.2 | K32: =parameter_metadata_original!K18 -> {"Recycled content [share - wt%]" : {"value":{"@value":"", "@type":"xsd:float", "unitCode":"P1"}}}
A33: =parameter_metadata_original!A20 -> 6. Circularity and resource efficiency | B33: =parameter_metadata_original!B20 -> x | C33: =parameter_metadata_original!C20 -> Circularity and resource efficiency | D33: =parameter_metadata_original!D20 -> Renewable content share | E33: 33 | G33: =parameter_metadata_original!G20 -> Public | H33: =parameter_metadata_original!H20 -> Static | I33: =parameter_metadata_original!I20 -> 0 | J33: 0 | K33: =parameter_metadata_original!K20 -> {"Renewable content share" : {"value":{"@value":"", "@type":"xsd:float", "unitCode":"P1"}}}
A34: =parameter_metadata_original!A21 -> 6. Circularity and resource efficiency | B34: =parameter_metadata_original!B21 -> x | C34: =parameter_metadata_original!C21 -> Circularity and resource efficiency | D34: =parameter_metadata_original!D21 -> Information on sources of spare parts | E34: 34 | G34: =parameter_metadata_original!G21 -> Public | H34: =parameter_metadata_original!H21 -> Static | I34: =parameter_metadata_original!I21 -> ONEPan AB, Bögatan 1, SE-412 72 Göteborg, Sweden | J34: =parameter_metadata_original!J21 -> File | K34: =parameter_metadata_original!K21 -> {"Information on sources of spare parts" : {"@type":"gs1:purchaseSuppliesOrAccessories", "value":{"@value":"", "@type":"xsd:anyURI"}}}
A35: =parameter_metadata_original!A24 -> 6. Circularity and resource efficiency | B35: =parameter_metadata_original!B24 -> x | C35: =parameter_metadata_original!C24 -> Durability | D35: =parameter_metadata_original!D24 -> Warranty period | E35: 35 | G35: =parameter_metadata_original!G24 -> Public | H35: =parameter_metadata_original!H24 -> Static | I35: =parameter_metadata_original!I24 -> Lifelong warranty through OnePans circular system | J35: =parameter_metadata_original!J24 -> Lifelong warranty through OnePans circular system | K35: =parameter_metadata_original!K24 -> {"Warranty period" : {"value":{"@value":"", "@type":"xsd:string"}}}
A36: =parameter_metadata_original!A25 -> 6. Circularity and resource efficiency | B36: =parameter_metadata_original!B25 -> x | C36: =parameter_metadata_original!C25 -> Durability | D36: =parameter_metadata_original!D25 -> Circular system Re-Coat | E36: 36 | G36: =parameter_metadata_original!G25 -> Public | H36: =parameter_metadata_original!H25 -> Static | I36: =parameter_metadata_original!I25 -> Through the OnePan circular system Re-Coat, OnePan can be recoated when the current coating wears out. Free of charge and forever. | J36: =parameter_metadata_original!J25 -> Through the OnePan circular system Re-Coat, OnePan can be recoated when the current coating wears out. Free of charge and forever. | K36: =parameter_metadata_original!K25 -> {"Circular system Re-Coat" : {"value":{"@value":"", "@type":"xsd:string"}}}
A37: =parameter_metadata_original!A38 -> 6. Circularity and resource efficiency | B37: =parameter_metadata_original!B38 -> x | C37: =parameter_metadata_original!C38 -> Reusability | D37: =parameter_metadata_original!D38 -> Recoating | E37: 37 | G37: =parameter_metadata_original!G38 -> Public | H37: =parameter_metadata_original!H38 -> Static | I37: =parameter_metadata_original!I38 -> Through the recoating process a used OnePan can be returned to an as-good-as-new-level. This process makes it possible to reuse a OnePan again and again and extend its life significantly. Instead of having to buy a new pan when the coating no longer function as intended. Also, the recoating process makes it possible to have a pan coating upgraded if a new formula is released. | J37: =parameter_metadata_original!J38 -> Through the recoating process a used OnePan can be returned to an as-good-as-new-level. This process makes it possible to reuse a OnePan again and again and extend its life significantly. Instead of having to buy a new pan when the coating no longer function as intended. Also, the recoating process makes it possible to have a pan coating upgraded if a new formula is released. | K37: =parameter_metadata_original!K38 -> {"Recoating" : {"value":{"@value":"", "@type":"xsd:string"}}}
A38: =parameter_metadata_original!A39 -> 6. Circularity and resource efficiency | B38: =parameter_metadata_original!B39 -> x | C38: =parameter_metadata_original!C39 -> Repairability | D38: =parameter_metadata_original!D39 -> Part numbers for spare parts | E38: 38 | G38: =parameter_metadata_original!G39 -> Public | H38: =parameter_metadata_original!H39 -> Static | I38: =parameter_metadata_original!I39 -> In case the handle should break (very unlikely though) it can be easily replaced. | J38: =parameter_metadata_original!J39 -> In case the handle should break (very unlikely though) it can be easily replaced. | K38: =parameter_metadata_original!K39 -> {"Part numbers for spare parts" : {"value":{"@value":"", "@type":"xsd:string"}}}
A39: =parameter_metadata_original!A40 -> 6. Circularity and resource efficiency | B39: =parameter_metadata_original!B40 -> x | C39: =parameter_metadata_original!C40 -> Maintenance and refurbishment | D39: =parameter_metadata_original!D40 -> Maintenance guidelines | E39: 39 | G39: =parameter_metadata_original!G40 -> Public | H39: =parameter_metadata_original!H40 -> Static | I39: =parameter_metadata_original!I40 -> Hur du tar hand om din OnePan – OnePan.se | J39: =parameter_metadata_original!J40 -> https://onepan.se/pages/hur-du-tar-hand-om-din-onepan?_gl=1*1a84e5*_up*MQ..*_gs*MQ..&gclid=EAIaIQobChMI6OPf8vezjAMVqWaRBR2K3SryEAAYASAAEgKRpPD_BwE | K39: =parameter_metadata_original!K40 -> {"Maintenance guidelines" : {"@type":"gs1:pip", "value":{"@value":"", "@type":"xsd:anyURI"}}}
A40: =parameter_metadata_original!A41 -> 6. Circularity and resource efficiency | B40: =parameter_metadata_original!B41 -> x | C40: =parameter_metadata_original!C41 -> Recyclability | D40: =parameter_metadata_original!D41 -> Dismantling information: Manuals for the removal and the disassembly of the product | E40: 40 | G40: =parameter_metadata_original!G41 -> Public | H40: =parameter_metadata_original!H41 -> Static | I40: =parameter_metadata_original!I41 -> The handle is attached to the pan body with a screw and can be easily removed. The body and bottom plate can be separated and recycled via the circular system and OnePan AB suppliers. | J40: =parameter_metadata_original!J41 -> The handle is attached to the pan body with a screw and can be easily removed. The body and bottom plate can be separated and recycled via the circular system and OnePan AB suppliers. | K40: =parameter_metadata_original!K41 -> {"Dismantling information: Manuals for the removal and the disassembly of the product" : {"value":{"@value":"", "@type":"xsd:string"}}}
...

Sheet parameter_metadata_original
A1: category | B1: Relevant for use case | C1: sub_category | D1: parameter | E1: order_parameter | F1: subparameter | G1: access | H1: type | I1: example data(text) | J1: example data | K1: data model definition string | L1: Data Type | M1: Unit/how to express
A2: 1. General product and manufacturer information | B2: x | C2: General product and manufacturer information | D2: DPP Created Timestamp | G2: Public | H2: Static | K2: {"DPP Created Timestamp" : {"value":{"@value":"", "@type":"xsd:dateTime"}}} | L2: Timestamp
A3: 1. General product and manufacturer information | B3: x | C3: General product and manufacturer information | D3: Product ID | G3: Public | H3: Static | K3: {"Product ID": {"@type":"gs1:gtin","value": {"@value":"", "@type":"xsd:string"}}} | L3: String
A4: 1. General product and manufacturer information | C4: General product and manufacturer information | D4: Data carrier type | G4: Public | H4: Static | I4: QR-code. Laser cut into material. | J4: QR-code. Laser cut into material. | K4: {"Data carrier type" : { "value": {"@value":"", "@type":"xsd:string"}}} | L4: String
A5: 1. General product and manufacturer information | B5: x | C5: General product and manufacturer information | D5: Manufacturing date | G5: Public | H5: Static | K5: {"Manufacturing date": {"@type":"gs1:productionDateTime", "value": {"@value":"", "@type":"xsd:dateTime"}}} | L5: Timestamp | M5: Date[YY-MM-DD]
A6: 1. General product and manufacturer information | B6: x | C6: General product and manufacturer information | D6: Manufactured by | G6: Public | H6: Static | I6: ONEPan AB, Bögatan 1, SE-412 72 Göteborg, Sweden | J6: ONEPan AB, Bögatan 1, SE-412 72 Göteborg, Sweden | K6: {"Manufactured by": {"@type":"gs1:organizationName", "value": {"@value": "", "@type":"xsd:string"}}} | L6: String
A7: 1. General product and manufacturer information | B7: x | C7: General product and manufacturer information | D7: Manufacturing place | F7: [City, Address] | G7: Public | H7: Static | I7: [Poland, Main Street 34] | J7: [Poland, Main Street 34] | K7: {"Manufacturing place" : {"@type":"gs1:address", "City": {"@type":"gs1:addressLocality", "value":{"@value": "", "@type":"xsd:string"}} , "Address":{"@type":"gs1:streetAddress", "value":{"@value": "", "@type":"xsd:string"}}}} | L7: String
A8: 1. General product and manufacturer information | B8: x | C8: General product and manufacturer information | D8: Product category | G8: Public | H8: Static | I8: Cookware | J8: Cookware | K8: {"Product category" : {"@type":"gs1:brandName", "value":{"@value":"", "@type":"rdf:langString"}}} | L8: String
A9: 1. General product and manufacturer information | B9: x | C9: General product and manufacturer information | D9: Economic operator | G9: Public | H9: Static | I9: ONEPan AB | J9: ONEPan AB | K9: {"Economic operator" : {"@type":"schema:legalName", "value": {"@value":"", "@type":"xsd:string"}}} | L9: String
A10: 9. Product Updates | B10: x | C10: 9. Product Updates | D10: Update ID | G10: Private | H10: Dynamic | I10: 1.1 | J10: 1.1 | K10: {"Update ID" : { "value": {"@value":"", "@type":"xsd:string"}}}
A11: 9. Product Updates | B11: x | C11: 9. Product Updates | D11: DPP Update Timestamp | G11: Private | H11: Dynamic | K11: {"DPP Update Timestamp" : {"@type":"schema:startTime", "value":{"@type":"schema:DateTime", "value": {"@value":"", "@type":"xsd:dateTime"}}}} | L11: Timestamp
A12: 9. Product Updates | B12: x | C12: 9. Product Updates | D12: DPP Update Reason | G12: Private | H12: Dynamic | K12: {"DPP Update Reason" : {"@type":"schema:description", "value":{"@type":"schema:Text", "value": {"@value":"", "@type":"xsd:string"}}}} | L12: String
A13: 9. Product Updates | B13: x | C13: 9. Product Updates | D13: DPP Update Responsible | G13: Private | H13: Dynamic | I13: ONEPan | J13: ONEPan | K13: {"DPP Update Responsible" : {"@type":"schema:Organization", "value":{"@type":"schema:legalName", "value": {"@value":"", "@type":"xsd:string"}}}}
A14: 1. General product and manufacturer information | B14: x | C14: Product specification | D14: Original weight | G14: Public | H14: Static | I14: 1.7 | J14: 2.7 | K14: {"Original weight" : {"value":{"@value":"", "@type":"xsd:float", "unitCode":"KGM"}}} | L14: Number | M14: kg
A15: 1. General product and manufacturer information | B15: x | C15: Product specification | D15: Dimensions | G15: Public | H15: Static | I15: Diameter 28 cm; Height 5 cm; Thickness bottom plate 0.55 cm; Handle length 21 cm | J15: Diameter 28 cm; Height 5 cm; Thickness bottom plate 0.55 cm; Handle length 21 cm | K15: {"Dimensions":{ "value": {"@value":"", "@type":"xsd:string"}}} | L15: String
A16: 6. Circularity and resource efficiency | B16: x | C16: Recycled content | D16: Recycled content | G16: Public | H16: Static | I16: Aluminium | J16: Aluminium | K16: {"Recycled content" : { "value": {"@value":"", "@type":"xsd:string"}}} | L16: String
A17: 6. Circularity and resource efficiency | B17: x | C17: Recycled content | D17: Recycled content weight | G17: Public | H17: Static | I17: 1.2 | J17: 1.2 | K17: {"Recycled content weight" : {"value":{"@value":"", "@type":"xsd:float", "unitCode":"KGM"}}} | L17: Number | M17: kg
A18: 6. Circularity and resource efficiency | B18: x | C18: Recycled content | D18: Recycled content [share - wt%] | G18: Public | H18: Static | I18: 70.2 | J18: 70.2 | K18: {"Recycled content [share - wt%]" : {"value":{"@value":"", "@type":"xsd:float", "unitCode":"P1"}}} | L18: Number | M18: %
A19: 5. Material and composition | B19: x | C19: Material and composition | D19: Hazardous substances, other than Hg, Cd, Pb | G19: Public | H19: Static | I19: No | J19: No | K19: {"Hazardous substances, other than Hg, Cd, Pb" : {"value":{"@value":"", "@type":"xsd:string"}}} | L19: String
A20: 6. Circularity and resource efficiency | B20: x | C20: Circularity and resource efficiency | D20: Renewable content share | G20: Public | H20: Static | I20: 0 | J20: 0 | K20: {"Renewable content share" : {"value":{"@value":"", "@type":"xsd:float", "unitCode":"P1"}}} | L20: Number | M20: %
A21: 6. Circularity and resource efficiency | B21: x | C21: Circularity and resource efficiency | D21: Information on sources of spare parts | G21: Public | H21: Static | I21: ONEPan AB, Bögatan 1, SE-412 72 Göteborg, Sweden | J21: File | K21: {"Information on sources of spare parts" : {"@type":"gs1:purchaseSuppliesOrAccessories", "value":{"@value":"", "@type":"xsd:anyURI"}}} | L21: File
A22: 1. General product and manufacturer information | B22: x | C22: General product and manufacturer information | D22: Date of purchase | G22: Public | H22: Static | K22: {"Date of purchase" : {"value":{"@value":"", "@type":"xsd:dateTime"}}} | L22: Timestamp
A23: 1. General product and manufacturer information | B23: x | C23: General product and manufacturer information | D23: Date of product registration on website | G23: Public | H23: Static | I23: 45541 | J23: 45541 | K23: {"Date of product registration on website" : {"value":{"@value":"", "@type":"xsd:dateTime"}}} | L23: Timestamp | M23: Hour
A24: 6. Circularity and resource efficiency | B24: x | C24: Durability | D24: Warranty period | G24: Public | H24: Static | I24: Lifelong warranty through OnePans circular system | J24: Lifelong warranty through OnePans circular system | K24: {"Warranty period" : {"value":{"@value":"", "@type":"xsd:string"}}} | L24: String
A25: 6. Circularity and resource efficiency | B25: x | C25: Durability | D25: Circular system Re-Coat | G25: Public | H25: Static | I25: Through the OnePan circular system Re-Coat, OnePan can be recoated when the current coating wears out. Free of charge and forever. | J25: Through the OnePan circular system Re-Coat, OnePan can be recoated when the current coating wears out. Free of charge and forever. | K25: {"Circular system Re-Coat" : {"value":{"@value":"", "@type":"xsd:string"}}} | L25: String
A26: 1. General product and manufacturer information | B26: x | C26: Product specification | D26: Ovenproof | G26: Public | H26: Static | I26: Withstands temperatures up to 280 ºC | J26: Withstands temperatures up to 280 ºC | K26: {"Ovenproof" : {"value":{"@value":"", "@type":"xsd:string"}}} | L26: String
A27: 1. General product and manufacturer information | B27: x | C27: Product specification | D27: Heat sources | G27: Public | H27: Static | I27: Suitable for all heat soruces: induction, gas, open fire | J27: Suitable for all heat soruces: induction, gas, open fire | K27: {"Heat sources" : {"value":{"@value":"", "@type":"xsd:string"}}} | L27: String
A28: 5. Material and composition | B28: x | C28: Components | D28: Number of components | G28: Public | H28: Static | I28: 3 | J28: 4 | K28: {"Number of components" : {"value":{"@value":"", "@type":"xsd:int"}}} | L28: Number
A29: 5. Material and composition | B29: x | C29: Components | D29: Components | G29: Public | H29: Static | I29: Bottom plate, pan body, handle, coating | J29: Bottom plate, pan body, handle, coating | K29: {"Components" : {"value":{"@value":"", "@type":"xsd:string"}}} | L29: String
A30: 5. Material and composition | B30: x | C30: Components | D30: Bottom plate content | G30: Public | H30: Static | I30: Stainless steel (magnetic) | J30: Stainless steel (magnetic) | K30: {"Bottom plate content" : {"value":{"@value":"", "@type":"xsd:string"}}} | L30: String
A31: 5. Material and composition | B31: x | C31: Components | D31: Pan body content | G31: Public | H31: Static | I31: Aluminium, 100% recycled | J31: Aluminium, 100% recycled | K31: {"Pan body content" : {"value":{"@value":"", "@type":"xsd:string"}}} | L31: String
A32: 5. Material and composition | B32: x | C32: Components | D32: Handle content | G32: Public | H32: Static | I32: Stainless steel | J32: Stainless steel | K32: {"Handle content" : {"value":{"@value":"", "@type":"xsd:string"}}} | L32: String
A33: 5. Material and composition | B33: x | C33: Components | D33: Coating content | G33: Public | H33: Static | I33: Ceramic non-stick, PFAS-free | J33: Ceramic non-stick, PFAS-free | K33: {"Coating content" : {"value":{"@value":"", "@type":"xsd:string"}}} | L33: String
A34: 5. Material and composition | B34: x | C34: Components | D34: Bottom plate weight | G34: Public | H34: Static | I34: 0.28 | J34: 0.28 | K34: {"Bottom plate weight" : {"value":{"@value":"", "@type":"xsd:float", "unitCode":"KGM"}}} | L34: Number | M34: kg
A35: 5. Material and composition | B35: x | C35: Components | D35: Pan body weight | G35: Public | H35: Static | I35: 1.2 | J35: 1.2 | K35: {"Pan body weight" : {"value":{"@value":"", "@type":"xsd:float", "unitCode":"KGM"}}} | L35: Number | M35: kg
A36: 5. Material and composition | B36: x | C36: Components | D36: Handle weight | G36: Public | H36: Static | I36: 0.22 | J36: 0.22 | K36: {"Handle weight" : {"value":{"@value":"", "@type":"xsd:float", "unitCode":"KGM"}}} | L36: Number | M36: kg
A37: 5. Material and composition | B37: x | C37: Components | D37: Coating weight | G37: Public | H37: Static | I37: < 0.010 | J37: < 0.011 | K37: {"Coating weight" : {"value":{"@value":"", "@type":"xsd:string", "unitCode":"KGM"}}} | L37: String | M37: kg
A38: 6. Circularity and resource efficiency | B38: x | C38: Reusability | D38: Recoating | G38: Public | H38: Static | I38: Through the recoating process a used OnePan can be returned to an as-good-as-new-level. This process makes it possible to reuse a OnePan again and again and extend its life significantly. Instead of having to buy a new pan when the coating no longer function as intended. Also, the recoating process makes it possible to have a pan coating upgraded if a new formula is released. | J38: Through the recoating process a used OnePan can be returned to an as-good-as-new-level. This process makes it possible to reuse a OnePan again and again and extend its life significantly. Instead of having to buy a new pan when the coating no longer function as intended. Also, the recoating process makes it possible to have a pan coating upgraded if a new formula is released. | K38: {"Recoating" : {"value":{"@value":"", "@type":"xsd:string"}}} | L38: String
A39: 6. Circularity and resource efficiency | B39: x | C39: Repairability | D39: Part numbers for spare parts | G39: Public | H39: Static | I39: In case the handle should break (very unlikely though) it can be easily replaced. | J39: In case the handle should break (very unlikely though) it can be easily replaced. | K39: {"Part numbers for spare parts" : {"value":{"@value":"", "@type":"xsd:string"}}} | L39: String
A40: 6. Circularity and resource efficiency | B40: x | C40: Maintenance and refurbishment | D40: Maintenance guidelines | G40: Public | H40: Static | I40: Hur du tar hand om din OnePan – OnePan.se | J40: https://onepan.se/pages/hur-du-tar-hand-om-din-onepan?_gl=1*1a84e5*_up*MQ..*_gs*MQ..&gclid=EAIaIQobChMI6OPf8vezjAMVqWaRBR2K3SryEAAYASAAEgKRpPD_BwE | K40: {"Maintenance guidelines" : {"@type":"gs1:pip", "value":{"@value":"", "@type":"xsd:anyURI"}}} | L40: URL
...

Sheet category_metadata
A1: category | B1: function_name | C1: icon_category
A2: 1. General product and manufacturer information | B2: general_product_and_manufacturer_information | C2: :material/quick_reference_all:
A3: 3. Carbon footprint | B3: carbon_footprint | C3: :material/footprint:
A4: 6. Circularity and resource efficiency | B4: circularity_and_resource_efficiency | C4: :material/cycle:
A5: 5. Material and composition | B5: material_and_composition | C5: :material/checklist_rtl:
A6: 9. Product Updates | B6: product_updates | C6: :material/update:

Sheet sub_category_metadata
A1: sub_category | B1: conf_print
A2: General product and manufacturer information | B2: strings
A3: 9. Product Updates | B3: table
A4: Product specification | B4: strings
A5: Recycled content | B5: strings
A6: Material and composition | B6: strings
A7: Circularity and resource efficiency | B7: strings
A8: Durability | B8: strings
A9: Components | B9: strings
A10: Reusability | B10: strings
A11: Repairability | B11: strings
A12: Maintenance and refurbishment | B12: strings
... A14: Carbon footprint | B14: strings
